ERROR 2022-07-21 18:10:02  "h11_impl.py" "run_asgi" "369" Exception in ASGI application
Traceback (most recent call last):
  File "/opt/homebrew/Caskroom/miniforge/base/lib/python3.9/site-packages/uvicorn/protocols/http/h11_impl.py", line 366, in run_asgi
    result = await app(self.scope, self.receive, self.send)
  File "/opt/homebrew/Caskroom/miniforge/base/lib/python3.9/site-packages/uvicorn/middleware/proxy_headers.py", line 75, in __call__
    return await self.app(scope, receive, send)
  File "/opt/homebrew/Caskroom/miniforge/base/lib/python3.9/site-packages/uvicorn/middleware/debug.py", line 96, in __call__
    raise exc from None
  File "/opt/homebrew/Caskroom/miniforge/base/lib/python3.9/site-packages/uvicorn/middleware/debug.py", line 93, in __call__
    await self.app(scope, receive, inner_send)
  File "/opt/homebrew/Caskroom/miniforge/base/lib/python3.9/site-packages/fastapi/applications.py", line 261, in __call__
    await super().__call__(scope, receive, send)
  File "/opt/homebrew/Caskroom/miniforge/base/lib/python3.9/site-packages/starlette/applications.py", line 119, in __call__
    await self.middleware_stack(scope, receive, send)
  File "/opt/homebrew/Caskroom/miniforge/base/lib/python3.9/site-packages/starlette/middleware/errors.py", line 181, in __call__
    raise exc
  File "/opt/homebrew/Caskroom/miniforge/base/lib/python3.9/site-packages/starlette/middleware/errors.py", line 159, in __call__
    await self.app(scope, receive, _send)
  File "/opt/homebrew/Caskroom/miniforge/base/lib/python3.9/site-packages/starlette/middleware/cors.py", line 92, in __call__
    await self.simple_response(scope, receive, send, request_headers=headers)
  File "/opt/homebrew/Caskroom/miniforge/base/lib/python3.9/site-packages/starlette/middleware/cors.py", line 147, in simple_response
    await self.app(scope, receive, send)
  File "/opt/homebrew/Caskroom/miniforge/base/lib/python3.9/site-packages/starlette/exceptions.py", line 87, in __call__
    raise exc
  File "/opt/homebrew/Caskroom/miniforge/base/lib/python3.9/site-packages/starlette/exceptions.py", line 76, in __call__
    await self.app(scope, receive, sender)
  File "/opt/homebrew/Caskroom/miniforge/base/lib/python3.9/site-packages/fastapi/middleware/asyncexitstack.py", line 21, in __call__
    raise e
  File "/opt/homebrew/Caskroom/miniforge/base/lib/python3.9/site-packages/fastapi/middleware/asyncexitstack.py", line 18, in __call__
    await self.app(scope, receive, send)
  File "/opt/homebrew/Caskroom/miniforge/base/lib/python3.9/site-packages/starlette/routing.py", line 659, in __call__
    await route.handle(scope, receive, send)
  File "/opt/homebrew/Caskroom/miniforge/base/lib/python3.9/site-packages/starlette/routing.py", line 259, in handle
    await self.app(scope, receive, send)
  File "/opt/homebrew/Caskroom/miniforge/base/lib/python3.9/site-packages/starlette/routing.py", line 61, in app
    response = await func(request)
  File "/opt/homebrew/Caskroom/miniforge/base/lib/python3.9/site-packages/fastapi/routing.py", line 227, in app
    raw_response = await run_endpoint_function(
  File "/opt/homebrew/Caskroom/miniforge/base/lib/python3.9/site-packages/fastapi/routing.py", line 160, in run_endpoint_function
    return await dependant.call(**values)
  File "/Users/beginner/Projects/temp/fastapi-vue/backend/app/apps/permission/views.py", line 55, in addUser
    curd_user.create(db, obj_in=obj)
  File "/Users/beginner/Projects/temp/fastapi-vue/backend/app/apps/permission/curd/curd_user.py", line 21, in create
    return super().create(db, obj_in=obj_in_data, creator_id=creator_id)
  File "/Users/beginner/Projects/temp/fastapi-vue/backend/app/common/curd_base.py", line 71, in create
    db_obj = self.model(**obj_in_data)  # type: ignore
  File "<string>", line 4, in __init__
  File "/opt/homebrew/Caskroom/miniforge/base/lib/python3.9/site-packages/sqlalchemy/orm/state.py", line 480, in _initialize_instance
    manager.dispatch.init_failure(self, args, kwargs)
  File "/opt/homebrew/Caskroom/miniforge/base/lib/python3.9/site-packages/sqlalchemy/util/langhelpers.py", line 70, in __exit__
    compat.raise_(
  File "/opt/homebrew/Caskroom/miniforge/base/lib/python3.9/site-packages/sqlalchemy/util/compat.py", line 207, in raise_
    raise exception
  File "/opt/homebrew/Caskroom/miniforge/base/lib/python3.9/site-packages/sqlalchemy/orm/state.py", line 477, in _initialize_instance
    return manager.original_init(*mixed[1:], **kwargs)
  File "/opt/homebrew/Caskroom/miniforge/base/lib/python3.9/site-packages/sqlalchemy/orm/decl_base.py", line 1163, in _declarative_constructor
    raise TypeError(
TypeError: 'roles' is an invalid keyword argument for Users
ERROR 2022-07-21 18:32:48  "h11_impl.py" "run_asgi" "369" Exception in ASGI application
Traceback (most recent call last):
  File "/opt/homebrew/Caskroom/miniforge/base/lib/python3.9/site-packages/uvicorn/protocols/http/h11_impl.py", line 366, in run_asgi
    result = await app(self.scope, self.receive, self.send)
  File "/opt/homebrew/Caskroom/miniforge/base/lib/python3.9/site-packages/uvicorn/middleware/proxy_headers.py", line 75, in __call__
    return await self.app(scope, receive, send)
  File "/opt/homebrew/Caskroom/miniforge/base/lib/python3.9/site-packages/uvicorn/middleware/debug.py", line 96, in __call__
    raise exc from None
  File "/opt/homebrew/Caskroom/miniforge/base/lib/python3.9/site-packages/uvicorn/middleware/debug.py", line 93, in __call__
    await self.app(scope, receive, inner_send)
  File "/opt/homebrew/Caskroom/miniforge/base/lib/python3.9/site-packages/fastapi/applications.py", line 261, in __call__
    await super().__call__(scope, receive, send)
  File "/opt/homebrew/Caskroom/miniforge/base/lib/python3.9/site-packages/starlette/applications.py", line 119, in __call__
    await self.middleware_stack(scope, receive, send)
  File "/opt/homebrew/Caskroom/miniforge/base/lib/python3.9/site-packages/starlette/middleware/errors.py", line 181, in __call__
    raise exc
  File "/opt/homebrew/Caskroom/miniforge/base/lib/python3.9/site-packages/starlette/middleware/errors.py", line 159, in __call__
    await self.app(scope, receive, _send)
  File "/opt/homebrew/Caskroom/miniforge/base/lib/python3.9/site-packages/starlette/middleware/cors.py", line 92, in __call__
    await self.simple_response(scope, receive, send, request_headers=headers)
  File "/opt/homebrew/Caskroom/miniforge/base/lib/python3.9/site-packages/starlette/middleware/cors.py", line 147, in simple_response
    await self.app(scope, receive, send)
  File "/opt/homebrew/Caskroom/miniforge/base/lib/python3.9/site-packages/starlette/exceptions.py", line 87, in __call__
    raise exc
  File "/opt/homebrew/Caskroom/miniforge/base/lib/python3.9/site-packages/starlette/exceptions.py", line 76, in __call__
    await self.app(scope, receive, sender)
  File "/opt/homebrew/Caskroom/miniforge/base/lib/python3.9/site-packages/fastapi/middleware/asyncexitstack.py", line 21, in __call__
    raise e
  File "/opt/homebrew/Caskroom/miniforge/base/lib/python3.9/site-packages/fastapi/middleware/asyncexitstack.py", line 18, in __call__
    await self.app(scope, receive, send)
  File "/opt/homebrew/Caskroom/miniforge/base/lib/python3.9/site-packages/starlette/routing.py", line 659, in __call__
    await route.handle(scope, receive, send)
  File "/opt/homebrew/Caskroom/miniforge/base/lib/python3.9/site-packages/starlette/routing.py", line 259, in handle
    await self.app(scope, receive, send)
  File "/opt/homebrew/Caskroom/miniforge/base/lib/python3.9/site-packages/starlette/routing.py", line 61, in app
    response = await func(request)
  File "/opt/homebrew/Caskroom/miniforge/base/lib/python3.9/site-packages/fastapi/routing.py", line 227, in app
    raw_response = await run_endpoint_function(
  File "/opt/homebrew/Caskroom/miniforge/base/lib/python3.9/site-packages/fastapi/routing.py", line 160, in run_endpoint_function
    return await dependant.call(**values)
  File "/Users/beginner/Projects/temp/fastapi-vue/backend/app/apps/permission/views.py", line 55, in addUser
    curd_user.create(db, obj_in=obj)
  File "/Users/beginner/Projects/temp/fastapi-vue/backend/app/apps/permission/curd/curd_user.py", line 26, in create
    obj_in_data.user_role = roles
AttributeError: 'dict' object has no attribute 'user_role'
ERROR 2022-07-21 18:33:27  "h11_impl.py" "run_asgi" "369" Exception in ASGI application
Traceback (most recent call last):
  File "/opt/homebrew/Caskroom/miniforge/base/lib/python3.9/site-packages/uvicorn/protocols/http/h11_impl.py", line 366, in run_asgi
    result = await app(self.scope, self.receive, self.send)
  File "/opt/homebrew/Caskroom/miniforge/base/lib/python3.9/site-packages/uvicorn/middleware/proxy_headers.py", line 75, in __call__
    return await self.app(scope, receive, send)
  File "/opt/homebrew/Caskroom/miniforge/base/lib/python3.9/site-packages/uvicorn/middleware/debug.py", line 96, in __call__
    raise exc from None
  File "/opt/homebrew/Caskroom/miniforge/base/lib/python3.9/site-packages/uvicorn/middleware/debug.py", line 93, in __call__
    await self.app(scope, receive, inner_send)
  File "/opt/homebrew/Caskroom/miniforge/base/lib/python3.9/site-packages/fastapi/applications.py", line 261, in __call__
    await super().__call__(scope, receive, send)
  File "/opt/homebrew/Caskroom/miniforge/base/lib/python3.9/site-packages/starlette/applications.py", line 119, in __call__
    await self.middleware_stack(scope, receive, send)
  File "/opt/homebrew/Caskroom/miniforge/base/lib/python3.9/site-packages/starlette/middleware/errors.py", line 181, in __call__
    raise exc
  File "/opt/homebrew/Caskroom/miniforge/base/lib/python3.9/site-packages/starlette/middleware/errors.py", line 159, in __call__
    await self.app(scope, receive, _send)
  File "/opt/homebrew/Caskroom/miniforge/base/lib/python3.9/site-packages/starlette/middleware/cors.py", line 92, in __call__
    await self.simple_response(scope, receive, send, request_headers=headers)
  File "/opt/homebrew/Caskroom/miniforge/base/lib/python3.9/site-packages/starlette/middleware/cors.py", line 147, in simple_response
    await self.app(scope, receive, send)
  File "/opt/homebrew/Caskroom/miniforge/base/lib/python3.9/site-packages/starlette/exceptions.py", line 87, in __call__
    raise exc
  File "/opt/homebrew/Caskroom/miniforge/base/lib/python3.9/site-packages/starlette/exceptions.py", line 76, in __call__
    await self.app(scope, receive, sender)
  File "/opt/homebrew/Caskroom/miniforge/base/lib/python3.9/site-packages/fastapi/middleware/asyncexitstack.py", line 21, in __call__
    raise e
  File "/opt/homebrew/Caskroom/miniforge/base/lib/python3.9/site-packages/fastapi/middleware/asyncexitstack.py", line 18, in __call__
    await self.app(scope, receive, send)
  File "/opt/homebrew/Caskroom/miniforge/base/lib/python3.9/site-packages/starlette/routing.py", line 659, in __call__
    await route.handle(scope, receive, send)
  File "/opt/homebrew/Caskroom/miniforge/base/lib/python3.9/site-packages/starlette/routing.py", line 259, in handle
    await self.app(scope, receive, send)
  File "/opt/homebrew/Caskroom/miniforge/base/lib/python3.9/site-packages/starlette/routing.py", line 61, in app
    response = await func(request)
  File "/opt/homebrew/Caskroom/miniforge/base/lib/python3.9/site-packages/fastapi/routing.py", line 227, in app
    raw_response = await run_endpoint_function(
  File "/opt/homebrew/Caskroom/miniforge/base/lib/python3.9/site-packages/fastapi/routing.py", line 160, in run_endpoint_function
    return await dependant.call(**values)
  File "/Users/beginner/Projects/temp/fastapi-vue/backend/app/apps/permission/views.py", line 55, in addUser
    curd_user.create(db, obj_in=obj)
  File "/Users/beginner/Projects/temp/fastapi-vue/backend/app/apps/permission/curd/curd_user.py", line 28, in create
    db.commit()
  File "/opt/homebrew/Caskroom/miniforge/base/lib/python3.9/site-packages/sqlalchemy/orm/session.py", line 1435, in commit
    self._transaction.commit(_to_root=self.future)
  File "/opt/homebrew/Caskroom/miniforge/base/lib/python3.9/site-packages/sqlalchemy/orm/session.py", line 829, in commit
    self._prepare_impl()
  File "/opt/homebrew/Caskroom/miniforge/base/lib/python3.9/site-packages/sqlalchemy/orm/session.py", line 808, in _prepare_impl
    self.session.flush()
  File "/opt/homebrew/Caskroom/miniforge/base/lib/python3.9/site-packages/sqlalchemy/orm/session.py", line 3367, in flush
    self._flush(objects)
  File "/opt/homebrew/Caskroom/miniforge/base/lib/python3.9/site-packages/sqlalchemy/orm/session.py", line 3507, in _flush
    transaction.rollback(_capture_exception=True)
  File "/opt/homebrew/Caskroom/miniforge/base/lib/python3.9/site-packages/sqlalchemy/util/langhelpers.py", line 70, in __exit__
    compat.raise_(
  File "/opt/homebrew/Caskroom/miniforge/base/lib/python3.9/site-packages/sqlalchemy/util/compat.py", line 207, in raise_
    raise exception
  File "/opt/homebrew/Caskroom/miniforge/base/lib/python3.9/site-packages/sqlalchemy/orm/session.py", line 3467, in _flush
    flush_context.execute()
  File "/opt/homebrew/Caskroom/miniforge/base/lib/python3.9/site-packages/sqlalchemy/orm/unitofwork.py", line 456, in execute
    rec.execute(self)
  File "/opt/homebrew/Caskroom/miniforge/base/lib/python3.9/site-packages/sqlalchemy/orm/unitofwork.py", line 630, in execute
    util.preloaded.orm_persistence.save_obj(
  File "/opt/homebrew/Caskroom/miniforge/base/lib/python3.9/site-packages/sqlalchemy/orm/persistence.py", line 245, in save_obj
    _emit_insert_statements(
  File "/opt/homebrew/Caskroom/miniforge/base/lib/python3.9/site-packages/sqlalchemy/orm/persistence.py", line 1238, in _emit_insert_statements
    result = connection._execute_20(
  File "/opt/homebrew/Caskroom/miniforge/base/lib/python3.9/site-packages/sqlalchemy/engine/base.py", line 1631, in _execute_20
    return meth(self, args_10style, kwargs_10style, execution_options)
  File "/opt/homebrew/Caskroom/miniforge/base/lib/python3.9/site-packages/sqlalchemy/sql/elements.py", line 325, in _execute_on_connection
    return connection._execute_clauseelement(
  File "/opt/homebrew/Caskroom/miniforge/base/lib/python3.9/site-packages/sqlalchemy/engine/base.py", line 1498, in _execute_clauseelement
    ret = self._execute_context(
  File "/opt/homebrew/Caskroom/miniforge/base/lib/python3.9/site-packages/sqlalchemy/engine/base.py", line 1862, in _execute_context
    self._handle_dbapi_exception(
  File "/opt/homebrew/Caskroom/miniforge/base/lib/python3.9/site-packages/sqlalchemy/engine/base.py", line 2043, in _handle_dbapi_exception
    util.raise_(
  File "/opt/homebrew/Caskroom/miniforge/base/lib/python3.9/site-packages/sqlalchemy/util/compat.py", line 207, in raise_
    raise exception
  File "/opt/homebrew/Caskroom/miniforge/base/lib/python3.9/site-packages/sqlalchemy/engine/base.py", line 1819, in _execute_context
    self.dialect.do_execute(
  File "/opt/homebrew/Caskroom/miniforge/base/lib/python3.9/site-packages/sqlalchemy/engine/default.py", line 732, in do_execute
    cursor.execute(statement, parameters)
  File "/opt/homebrew/Caskroom/miniforge/base/lib/python3.9/site-packages/pymysql/cursors.py", line 148, in execute
    result = self._query(query)
  File "/opt/homebrew/Caskroom/miniforge/base/lib/python3.9/site-packages/pymysql/cursors.py", line 310, in _query
    conn.query(q)
  File "/opt/homebrew/Caskroom/miniforge/base/lib/python3.9/site-packages/pymysql/connections.py", line 548, in query
    self._affected_rows = self._read_query_result(unbuffered=unbuffered)
  File "/opt/homebrew/Caskroom/miniforge/base/lib/python3.9/site-packages/pymysql/connections.py", line 775, in _read_query_result
    result.read()
  File "/opt/homebrew/Caskroom/miniforge/base/lib/python3.9/site-packages/pymysql/connections.py", line 1156, in read
    first_packet = self.connection._read_packet()
  File "/opt/homebrew/Caskroom/miniforge/base/lib/python3.9/site-packages/pymysql/connections.py", line 725, in _read_packet
    packet.raise_for_error()
  File "/opt/homebrew/Caskroom/miniforge/base/lib/python3.9/site-packages/pymysql/protocol.py", line 221, in raise_for_error
    err.raise_mysql_exception(self._data)
  File "/opt/homebrew/Caskroom/miniforge/base/lib/python3.9/site-packages/pymysql/err.py", line 143, in raise_mysql_exception
    raise errorclass(errno, errval)
sqlalchemy.exc.IntegrityError: (pymysql.err.IntegrityError) (1048, "Column 'hashed_password' cannot be null")
[SQL: INSERT INTO t_users (created_time, creator_id, modified_time, modifier_id, is_deleted, username, nickname, sex, phone, email, hashed_password, avatar, status, is_active) VALUES (%(created_time)s, %(creator_id)s, %(modified_time)s, %(modifier_id)s, %(is_deleted)s, %(username)s, %(nickname)s, %(sex)s, %(phone)s, %(email)s, %(hashed_password)s, %(avatar)s, %(status)s, %(is_active)s)]
[parameters: {'created_time': datetime.datetime(2022, 7, 21, 18, 33, 27, 277358), 'creator_id': 0, 'modified_time': datetime.datetime(2022, 7, 21, 18, 33, 27, 277367), 'modifier_id': 0, 'is_deleted': 0, 'username': 'aaaaa', 'nickname': 'aa', 'sex': 0, 'phone': '12345678911', 'email': 'aa@test.com', 'hashed_password': None, 'avatar': '', 'status': 0, 'is_active': 0}]
(Background on this error at: https://sqlalche.me/e/14/gkpj)
ERROR 2022-07-21 19:41:19  "h11_impl.py" "run_asgi" "369" Exception in ASGI application
Traceback (most recent call last):
  File "/opt/homebrew/Caskroom/miniforge/base/lib/python3.9/site-packages/uvicorn/protocols/http/h11_impl.py", line 366, in run_asgi
    result = await app(self.scope, self.receive, self.send)
  File "/opt/homebrew/Caskroom/miniforge/base/lib/python3.9/site-packages/uvicorn/middleware/proxy_headers.py", line 75, in __call__
    return await self.app(scope, receive, send)
  File "/opt/homebrew/Caskroom/miniforge/base/lib/python3.9/site-packages/uvicorn/middleware/debug.py", line 96, in __call__
    raise exc from None
  File "/opt/homebrew/Caskroom/miniforge/base/lib/python3.9/site-packages/uvicorn/middleware/debug.py", line 93, in __call__
    await self.app(scope, receive, inner_send)
  File "/opt/homebrew/Caskroom/miniforge/base/lib/python3.9/site-packages/fastapi/applications.py", line 261, in __call__
    await super().__call__(scope, receive, send)
  File "/opt/homebrew/Caskroom/miniforge/base/lib/python3.9/site-packages/starlette/applications.py", line 119, in __call__
    await self.middleware_stack(scope, receive, send)
  File "/opt/homebrew/Caskroom/miniforge/base/lib/python3.9/site-packages/starlette/middleware/errors.py", line 181, in __call__
    raise exc
  File "/opt/homebrew/Caskroom/miniforge/base/lib/python3.9/site-packages/starlette/middleware/errors.py", line 159, in __call__
    await self.app(scope, receive, _send)
  File "/opt/homebrew/Caskroom/miniforge/base/lib/python3.9/site-packages/starlette/middleware/cors.py", line 92, in __call__
    await self.simple_response(scope, receive, send, request_headers=headers)
  File "/opt/homebrew/Caskroom/miniforge/base/lib/python3.9/site-packages/starlette/middleware/cors.py", line 147, in simple_response
    await self.app(scope, receive, send)
  File "/opt/homebrew/Caskroom/miniforge/base/lib/python3.9/site-packages/starlette/exceptions.py", line 87, in __call__
    raise exc
  File "/opt/homebrew/Caskroom/miniforge/base/lib/python3.9/site-packages/starlette/exceptions.py", line 76, in __call__
    await self.app(scope, receive, sender)
  File "/opt/homebrew/Caskroom/miniforge/base/lib/python3.9/site-packages/fastapi/middleware/asyncexitstack.py", line 21, in __call__
    raise e
  File "/opt/homebrew/Caskroom/miniforge/base/lib/python3.9/site-packages/fastapi/middleware/asyncexitstack.py", line 18, in __call__
    await self.app(scope, receive, send)
  File "/opt/homebrew/Caskroom/miniforge/base/lib/python3.9/site-packages/starlette/routing.py", line 659, in __call__
    await route.handle(scope, receive, send)
  File "/opt/homebrew/Caskroom/miniforge/base/lib/python3.9/site-packages/starlette/routing.py", line 259, in handle
    await self.app(scope, receive, send)
  File "/opt/homebrew/Caskroom/miniforge/base/lib/python3.9/site-packages/starlette/routing.py", line 61, in app
    response = await func(request)
  File "/opt/homebrew/Caskroom/miniforge/base/lib/python3.9/site-packages/fastapi/routing.py", line 227, in app
    raw_response = await run_endpoint_function(
  File "/opt/homebrew/Caskroom/miniforge/base/lib/python3.9/site-packages/fastapi/routing.py", line 160, in run_endpoint_function
    return await dependant.call(**values)
  File "/Users/beginner/Projects/temp/fastapi-vue/backend/app/apps/permission/views.py", line 65, in setUser
    curd_user.update(db, _id=user_id, obj_in=obj)
  File "/Users/beginner/Projects/temp/fastapi-vue/backend/app/apps/permission/curd/curd_user.py", line 64, in update
    self.setUserRoles(db, user_id=_id, role_ids=roles, ctl_id=updater_id)
  File "/Users/beginner/Projects/temp/fastapi-vue/backend/app/apps/permission/curd/curd_user.py", line 71, in setUserRoles
    db.commit()
  File "/opt/homebrew/Caskroom/miniforge/base/lib/python3.9/site-packages/sqlalchemy/orm/session.py", line 1435, in commit
    self._transaction.commit(_to_root=self.future)
  File "/opt/homebrew/Caskroom/miniforge/base/lib/python3.9/site-packages/sqlalchemy/orm/session.py", line 829, in commit
    self._prepare_impl()
  File "/opt/homebrew/Caskroom/miniforge/base/lib/python3.9/site-packages/sqlalchemy/orm/session.py", line 808, in _prepare_impl
    self.session.flush()
  File "/opt/homebrew/Caskroom/miniforge/base/lib/python3.9/site-packages/sqlalchemy/orm/session.py", line 3367, in flush
    self._flush(objects)
  File "/opt/homebrew/Caskroom/miniforge/base/lib/python3.9/site-packages/sqlalchemy/orm/session.py", line 3507, in _flush
    transaction.rollback(_capture_exception=True)
  File "/opt/homebrew/Caskroom/miniforge/base/lib/python3.9/site-packages/sqlalchemy/util/langhelpers.py", line 70, in __exit__
    compat.raise_(
  File "/opt/homebrew/Caskroom/miniforge/base/lib/python3.9/site-packages/sqlalchemy/util/compat.py", line 207, in raise_
    raise exception
  File "/opt/homebrew/Caskroom/miniforge/base/lib/python3.9/site-packages/sqlalchemy/orm/session.py", line 3467, in _flush
    flush_context.execute()
  File "/opt/homebrew/Caskroom/miniforge/base/lib/python3.9/site-packages/sqlalchemy/orm/unitofwork.py", line 456, in execute
    rec.execute(self)
  File "/opt/homebrew/Caskroom/miniforge/base/lib/python3.9/site-packages/sqlalchemy/orm/unitofwork.py", line 630, in execute
    util.preloaded.orm_persistence.save_obj(
  File "/opt/homebrew/Caskroom/miniforge/base/lib/python3.9/site-packages/sqlalchemy/orm/persistence.py", line 245, in save_obj
    _emit_insert_statements(
  File "/opt/homebrew/Caskroom/miniforge/base/lib/python3.9/site-packages/sqlalchemy/orm/persistence.py", line 1238, in _emit_insert_statements
    result = connection._execute_20(
  File "/opt/homebrew/Caskroom/miniforge/base/lib/python3.9/site-packages/sqlalchemy/engine/base.py", line 1631, in _execute_20
    return meth(self, args_10style, kwargs_10style, execution_options)
  File "/opt/homebrew/Caskroom/miniforge/base/lib/python3.9/site-packages/sqlalchemy/sql/elements.py", line 325, in _execute_on_connection
    return connection._execute_clauseelement(
  File "/opt/homebrew/Caskroom/miniforge/base/lib/python3.9/site-packages/sqlalchemy/engine/base.py", line 1498, in _execute_clauseelement
    ret = self._execute_context(
  File "/opt/homebrew/Caskroom/miniforge/base/lib/python3.9/site-packages/sqlalchemy/engine/base.py", line 1862, in _execute_context
    self._handle_dbapi_exception(
  File "/opt/homebrew/Caskroom/miniforge/base/lib/python3.9/site-packages/sqlalchemy/engine/base.py", line 2043, in _handle_dbapi_exception
    util.raise_(
  File "/opt/homebrew/Caskroom/miniforge/base/lib/python3.9/site-packages/sqlalchemy/util/compat.py", line 207, in raise_
    raise exception
  File "/opt/homebrew/Caskroom/miniforge/base/lib/python3.9/site-packages/sqlalchemy/engine/base.py", line 1819, in _execute_context
    self.dialect.do_execute(
  File "/opt/homebrew/Caskroom/miniforge/base/lib/python3.9/site-packages/sqlalchemy/engine/default.py", line 732, in do_execute
    cursor.execute(statement, parameters)
  File "/opt/homebrew/Caskroom/miniforge/base/lib/python3.9/site-packages/pymysql/cursors.py", line 148, in execute
    result = self._query(query)
  File "/opt/homebrew/Caskroom/miniforge/base/lib/python3.9/site-packages/pymysql/cursors.py", line 310, in _query
    conn.query(q)
  File "/opt/homebrew/Caskroom/miniforge/base/lib/python3.9/site-packages/pymysql/connections.py", line 548, in query
    self._affected_rows = self._read_query_result(unbuffered=unbuffered)
  File "/opt/homebrew/Caskroom/miniforge/base/lib/python3.9/site-packages/pymysql/connections.py", line 775, in _read_query_result
    result.read()
  File "/opt/homebrew/Caskroom/miniforge/base/lib/python3.9/site-packages/pymysql/connections.py", line 1156, in read
    first_packet = self.connection._read_packet()
  File "/opt/homebrew/Caskroom/miniforge/base/lib/python3.9/site-packages/pymysql/connections.py", line 725, in _read_packet
    packet.raise_for_error()
  File "/opt/homebrew/Caskroom/miniforge/base/lib/python3.9/site-packages/pymysql/protocol.py", line 221, in raise_for_error
    err.raise_mysql_exception(self._data)
  File "/opt/homebrew/Caskroom/miniforge/base/lib/python3.9/site-packages/pymysql/err.py", line 143, in raise_mysql_exception
    raise errorclass(errno, errval)
sqlalchemy.exc.DataError: (pymysql.err.DataError) (1366, "Incorrect integer value: '<apps.permission.models.role.Roles object at 0x11c542850>' for column 'role_id' at row 1")
[SQL: INSERT INTO t_user_role (created_time, creator_id, modified_time, modifier_id, is_deleted, user_id, role_id) VALUES (%(created_time)s, %(creator_id)s, %(modified_time)s, %(modifier_id)s, %(is_deleted)s, %(user_id)s, %(role_id)s)]
[parameters: {'created_time': datetime.datetime(2022, 7, 21, 19, 41, 19, 987026), 'creator_id': 0, 'modified_time': datetime.datetime(2022, 7, 21, 19, 41, 19, 987047), 'modifier_id': 0, 'is_deleted': 0, 'user_id': 3, 'role_id': <apps.permission.models.role.Roles object at 0x11c542850>}]
(Background on this error at: https://sqlalche.me/e/14/9h9h)
ERROR 2022-07-22 16:02:24  "h11_impl.py" "run_asgi" "369" Exception in ASGI application
Traceback (most recent call last):
  File "/opt/homebrew/Caskroom/miniforge/base/lib/python3.9/site-packages/uvicorn/protocols/http/h11_impl.py", line 366, in run_asgi
    result = await app(self.scope, self.receive, self.send)
  File "/opt/homebrew/Caskroom/miniforge/base/lib/python3.9/site-packages/uvicorn/middleware/proxy_headers.py", line 75, in __call__
    return await self.app(scope, receive, send)
  File "/opt/homebrew/Caskroom/miniforge/base/lib/python3.9/site-packages/uvicorn/middleware/debug.py", line 96, in __call__
    raise exc from None
  File "/opt/homebrew/Caskroom/miniforge/base/lib/python3.9/site-packages/uvicorn/middleware/debug.py", line 93, in __call__
    await self.app(scope, receive, inner_send)
  File "/opt/homebrew/Caskroom/miniforge/base/lib/python3.9/site-packages/fastapi/applications.py", line 261, in __call__
    await super().__call__(scope, receive, send)
  File "/opt/homebrew/Caskroom/miniforge/base/lib/python3.9/site-packages/starlette/applications.py", line 119, in __call__
    await self.middleware_stack(scope, receive, send)
  File "/opt/homebrew/Caskroom/miniforge/base/lib/python3.9/site-packages/starlette/middleware/errors.py", line 181, in __call__
    raise exc
  File "/opt/homebrew/Caskroom/miniforge/base/lib/python3.9/site-packages/starlette/middleware/errors.py", line 159, in __call__
    await self.app(scope, receive, _send)
  File "/opt/homebrew/Caskroom/miniforge/base/lib/python3.9/site-packages/starlette/middleware/cors.py", line 92, in __call__
    await self.simple_response(scope, receive, send, request_headers=headers)
  File "/opt/homebrew/Caskroom/miniforge/base/lib/python3.9/site-packages/starlette/middleware/cors.py", line 147, in simple_response
    await self.app(scope, receive, send)
  File "/opt/homebrew/Caskroom/miniforge/base/lib/python3.9/site-packages/starlette/exceptions.py", line 87, in __call__
    raise exc
  File "/opt/homebrew/Caskroom/miniforge/base/lib/python3.9/site-packages/starlette/exceptions.py", line 76, in __call__
    await self.app(scope, receive, sender)
  File "/opt/homebrew/Caskroom/miniforge/base/lib/python3.9/site-packages/fastapi/middleware/asyncexitstack.py", line 21, in __call__
    raise e
  File "/opt/homebrew/Caskroom/miniforge/base/lib/python3.9/site-packages/fastapi/middleware/asyncexitstack.py", line 18, in __call__
    await self.app(scope, receive, send)
  File "/opt/homebrew/Caskroom/miniforge/base/lib/python3.9/site-packages/starlette/routing.py", line 659, in __call__
    await route.handle(scope, receive, send)
  File "/opt/homebrew/Caskroom/miniforge/base/lib/python3.9/site-packages/starlette/routing.py", line 259, in handle
    await self.app(scope, receive, send)
  File "/opt/homebrew/Caskroom/miniforge/base/lib/python3.9/site-packages/starlette/routing.py", line 61, in app
    response = await func(request)
  File "/opt/homebrew/Caskroom/miniforge/base/lib/python3.9/site-packages/fastapi/routing.py", line 227, in app
    raw_response = await run_endpoint_function(
  File "/opt/homebrew/Caskroom/miniforge/base/lib/python3.9/site-packages/fastapi/routing.py", line 160, in run_endpoint_function
    return await dependant.call(**values)
  File "/Users/beginner/Projects/temp/fastapi-vue/backend/app/apps/permission/views.py", line 235, in uploadAvatar
    imgname = img.filename  # type: str
AttributeError: 'bytes' object has no attribute 'filename'
ERROR 2022-07-22 16:06:47  "h11_impl.py" "run_asgi" "369" Exception in ASGI application
Traceback (most recent call last):
  File "/opt/homebrew/Caskroom/miniforge/base/lib/python3.9/site-packages/uvicorn/protocols/http/h11_impl.py", line 366, in run_asgi
    result = await app(self.scope, self.receive, self.send)
  File "/opt/homebrew/Caskroom/miniforge/base/lib/python3.9/site-packages/uvicorn/middleware/proxy_headers.py", line 75, in __call__
    return await self.app(scope, receive, send)
  File "/opt/homebrew/Caskroom/miniforge/base/lib/python3.9/site-packages/uvicorn/middleware/debug.py", line 96, in __call__
    raise exc from None
  File "/opt/homebrew/Caskroom/miniforge/base/lib/python3.9/site-packages/uvicorn/middleware/debug.py", line 93, in __call__
    await self.app(scope, receive, inner_send)
  File "/opt/homebrew/Caskroom/miniforge/base/lib/python3.9/site-packages/fastapi/applications.py", line 261, in __call__
    await super().__call__(scope, receive, send)
  File "/opt/homebrew/Caskroom/miniforge/base/lib/python3.9/site-packages/starlette/applications.py", line 119, in __call__
    await self.middleware_stack(scope, receive, send)
  File "/opt/homebrew/Caskroom/miniforge/base/lib/python3.9/site-packages/starlette/middleware/errors.py", line 181, in __call__
    raise exc
  File "/opt/homebrew/Caskroom/miniforge/base/lib/python3.9/site-packages/starlette/middleware/errors.py", line 159, in __call__
    await self.app(scope, receive, _send)
  File "/opt/homebrew/Caskroom/miniforge/base/lib/python3.9/site-packages/starlette/middleware/cors.py", line 92, in __call__
    await self.simple_response(scope, receive, send, request_headers=headers)
  File "/opt/homebrew/Caskroom/miniforge/base/lib/python3.9/site-packages/starlette/middleware/cors.py", line 147, in simple_response
    await self.app(scope, receive, send)
  File "/opt/homebrew/Caskroom/miniforge/base/lib/python3.9/site-packages/starlette/exceptions.py", line 87, in __call__
    raise exc
  File "/opt/homebrew/Caskroom/miniforge/base/lib/python3.9/site-packages/starlette/exceptions.py", line 76, in __call__
    await self.app(scope, receive, sender)
  File "/opt/homebrew/Caskroom/miniforge/base/lib/python3.9/site-packages/fastapi/middleware/asyncexitstack.py", line 21, in __call__
    raise e
  File "/opt/homebrew/Caskroom/miniforge/base/lib/python3.9/site-packages/fastapi/middleware/asyncexitstack.py", line 18, in __call__
    await self.app(scope, receive, send)
  File "/opt/homebrew/Caskroom/miniforge/base/lib/python3.9/site-packages/starlette/routing.py", line 659, in __call__
    await route.handle(scope, receive, send)
  File "/opt/homebrew/Caskroom/miniforge/base/lib/python3.9/site-packages/starlette/routing.py", line 259, in handle
    await self.app(scope, receive, send)
  File "/opt/homebrew/Caskroom/miniforge/base/lib/python3.9/site-packages/starlette/routing.py", line 61, in app
    response = await func(request)
  File "/opt/homebrew/Caskroom/miniforge/base/lib/python3.9/site-packages/fastapi/routing.py", line 227, in app
    raw_response = await run_endpoint_function(
  File "/opt/homebrew/Caskroom/miniforge/base/lib/python3.9/site-packages/fastapi/routing.py", line 160, in run_endpoint_function
    return await dependant.call(**values)
  File "/Users/beginner/Projects/temp/fastapi-vue/backend/app/apps/permission/views.py", line 238, in uploadAvatar
    with open(os.path.join(constants.BASE_DIR, path), 'wb') as f:
FileNotFoundError: [Errno 2] No such file or directory: '/Users/beginner/Projects/temp/fastapi-vue/backend/app/images/avatar/464165cbb0d54659a40fe61736751f1cpng'
ERROR 2022-07-22 18:01:44  "h11_impl.py" "run_asgi" "369" Exception in ASGI application
Traceback (most recent call last):
  File "/opt/homebrew/Caskroom/miniforge/base/lib/python3.9/site-packages/uvicorn/protocols/http/h11_impl.py", line 366, in run_asgi
    result = await app(self.scope, self.receive, self.send)
  File "/opt/homebrew/Caskroom/miniforge/base/lib/python3.9/site-packages/uvicorn/middleware/proxy_headers.py", line 75, in __call__
    return await self.app(scope, receive, send)
  File "/opt/homebrew/Caskroom/miniforge/base/lib/python3.9/site-packages/uvicorn/middleware/debug.py", line 96, in __call__
    raise exc from None
  File "/opt/homebrew/Caskroom/miniforge/base/lib/python3.9/site-packages/uvicorn/middleware/debug.py", line 93, in __call__
    await self.app(scope, receive, inner_send)
  File "/opt/homebrew/Caskroom/miniforge/base/lib/python3.9/site-packages/fastapi/applications.py", line 261, in __call__
    await super().__call__(scope, receive, send)
  File "/opt/homebrew/Caskroom/miniforge/base/lib/python3.9/site-packages/starlette/applications.py", line 119, in __call__
    await self.middleware_stack(scope, receive, send)
  File "/opt/homebrew/Caskroom/miniforge/base/lib/python3.9/site-packages/starlette/middleware/errors.py", line 181, in __call__
    raise exc
  File "/opt/homebrew/Caskroom/miniforge/base/lib/python3.9/site-packages/starlette/middleware/errors.py", line 159, in __call__
    await self.app(scope, receive, _send)
  File "/opt/homebrew/Caskroom/miniforge/base/lib/python3.9/site-packages/starlette/middleware/cors.py", line 92, in __call__
    await self.simple_response(scope, receive, send, request_headers=headers)
  File "/opt/homebrew/Caskroom/miniforge/base/lib/python3.9/site-packages/starlette/middleware/cors.py", line 147, in simple_response
    await self.app(scope, receive, send)
  File "/opt/homebrew/Caskroom/miniforge/base/lib/python3.9/site-packages/starlette/exceptions.py", line 87, in __call__
    raise exc
  File "/opt/homebrew/Caskroom/miniforge/base/lib/python3.9/site-packages/starlette/exceptions.py", line 76, in __call__
    await self.app(scope, receive, sender)
  File "/opt/homebrew/Caskroom/miniforge/base/lib/python3.9/site-packages/fastapi/middleware/asyncexitstack.py", line 21, in __call__
    raise e
  File "/opt/homebrew/Caskroom/miniforge/base/lib/python3.9/site-packages/fastapi/middleware/asyncexitstack.py", line 18, in __call__
    await self.app(scope, receive, send)
  File "/opt/homebrew/Caskroom/miniforge/base/lib/python3.9/site-packages/starlette/routing.py", line 659, in __call__
    await route.handle(scope, receive, send)
  File "/opt/homebrew/Caskroom/miniforge/base/lib/python3.9/site-packages/starlette/routing.py", line 259, in handle
    await self.app(scope, receive, send)
  File "/opt/homebrew/Caskroom/miniforge/base/lib/python3.9/site-packages/starlette/routing.py", line 61, in app
    response = await func(request)
  File "/opt/homebrew/Caskroom/miniforge/base/lib/python3.9/site-packages/fastapi/routing.py", line 227, in app
    raw_response = await run_endpoint_function(
  File "/opt/homebrew/Caskroom/miniforge/base/lib/python3.9/site-packages/fastapi/routing.py", line 160, in run_endpoint_function
    return await dependant.call(**values)
  File "/Users/beginner/Projects/temp/fastapi-vue/backend/app/apps/system/views.py", line 44, in getConfigSettingByKey
    config_setting_obj = curd_config_setting.getByKey(db, key=key)
  File "/Users/beginner/Projects/temp/fastapi-vue/backend/app/apps/system/curd/curd_config_setting.py", line 11, in getByKey
    obj = db.query(*self.query_columns).filter(self.model.key == key, self.model.is_delete == 0,
AttributeError: type object 'ConfigSettings' has no attribute 'is_delete'
ERROR 2022-07-22 19:24:42  "h11_impl.py" "run_asgi" "369" Exception in ASGI application
Traceback (most recent call last):
  File "/opt/homebrew/Caskroom/miniforge/base/lib/python3.9/site-packages/uvicorn/protocols/http/h11_impl.py", line 366, in run_asgi
    result = await app(self.scope, self.receive, self.send)
  File "/opt/homebrew/Caskroom/miniforge/base/lib/python3.9/site-packages/uvicorn/middleware/proxy_headers.py", line 75, in __call__
    return await self.app(scope, receive, send)
  File "/opt/homebrew/Caskroom/miniforge/base/lib/python3.9/site-packages/uvicorn/middleware/debug.py", line 96, in __call__
    raise exc from None
  File "/opt/homebrew/Caskroom/miniforge/base/lib/python3.9/site-packages/uvicorn/middleware/debug.py", line 93, in __call__
    await self.app(scope, receive, inner_send)
  File "/opt/homebrew/Caskroom/miniforge/base/lib/python3.9/site-packages/fastapi/applications.py", line 261, in __call__
    await super().__call__(scope, receive, send)
  File "/opt/homebrew/Caskroom/miniforge/base/lib/python3.9/site-packages/starlette/applications.py", line 119, in __call__
    await self.middleware_stack(scope, receive, send)
  File "/opt/homebrew/Caskroom/miniforge/base/lib/python3.9/site-packages/starlette/middleware/errors.py", line 181, in __call__
    raise exc
  File "/opt/homebrew/Caskroom/miniforge/base/lib/python3.9/site-packages/starlette/middleware/errors.py", line 159, in __call__
    await self.app(scope, receive, _send)
  File "/opt/homebrew/Caskroom/miniforge/base/lib/python3.9/site-packages/starlette/middleware/cors.py", line 92, in __call__
    await self.simple_response(scope, receive, send, request_headers=headers)
  File "/opt/homebrew/Caskroom/miniforge/base/lib/python3.9/site-packages/starlette/middleware/cors.py", line 147, in simple_response
    await self.app(scope, receive, send)
  File "/opt/homebrew/Caskroom/miniforge/base/lib/python3.9/site-packages/starlette/exceptions.py", line 87, in __call__
    raise exc
  File "/opt/homebrew/Caskroom/miniforge/base/lib/python3.9/site-packages/starlette/exceptions.py", line 76, in __call__
    await self.app(scope, receive, sender)
  File "/opt/homebrew/Caskroom/miniforge/base/lib/python3.9/site-packages/fastapi/middleware/asyncexitstack.py", line 21, in __call__
    raise e
  File "/opt/homebrew/Caskroom/miniforge/base/lib/python3.9/site-packages/fastapi/middleware/asyncexitstack.py", line 18, in __call__
    await self.app(scope, receive, send)
  File "/opt/homebrew/Caskroom/miniforge/base/lib/python3.9/site-packages/starlette/routing.py", line 659, in __call__
    await route.handle(scope, receive, send)
  File "/opt/homebrew/Caskroom/miniforge/base/lib/python3.9/site-packages/starlette/routing.py", line 259, in handle
    await self.app(scope, receive, send)
  File "/opt/homebrew/Caskroom/miniforge/base/lib/python3.9/site-packages/starlette/routing.py", line 61, in app
    response = await func(request)
  File "/opt/homebrew/Caskroom/miniforge/base/lib/python3.9/site-packages/fastapi/routing.py", line 227, in app
    raw_response = await run_endpoint_function(
  File "/opt/homebrew/Caskroom/miniforge/base/lib/python3.9/site-packages/fastapi/routing.py", line 160, in run_endpoint_function
    return await dependant.call(**values)
  File "/Users/beginner/Projects/temp/fastapi-vue/backend/app/apps/permission/views.py", line 91, in setIsActive
    curd_user.update(db, _id=user_id, obj_in=obj)
  File "/Users/beginner/Projects/temp/fastapi-vue/backend/app/apps/permission/curd/curd_user.py", line 58, in update
    del obj_in_data['roles']
KeyError: 'roles'
ERROR 2022-07-22 19:29:03  "h11_impl.py" "run_asgi" "369" Exception in ASGI application
Traceback (most recent call last):
  File "/opt/homebrew/Caskroom/miniforge/base/lib/python3.9/site-packages/uvicorn/protocols/http/h11_impl.py", line 366, in run_asgi
    result = await app(self.scope, self.receive, self.send)
  File "/opt/homebrew/Caskroom/miniforge/base/lib/python3.9/site-packages/uvicorn/middleware/proxy_headers.py", line 75, in __call__
    return await self.app(scope, receive, send)
  File "/opt/homebrew/Caskroom/miniforge/base/lib/python3.9/site-packages/uvicorn/middleware/debug.py", line 96, in __call__
    raise exc from None
  File "/opt/homebrew/Caskroom/miniforge/base/lib/python3.9/site-packages/uvicorn/middleware/debug.py", line 93, in __call__
    await self.app(scope, receive, inner_send)
  File "/opt/homebrew/Caskroom/miniforge/base/lib/python3.9/site-packages/fastapi/applications.py", line 261, in __call__
    await super().__call__(scope, receive, send)
  File "/opt/homebrew/Caskroom/miniforge/base/lib/python3.9/site-packages/starlette/applications.py", line 119, in __call__
    await self.middleware_stack(scope, receive, send)
  File "/opt/homebrew/Caskroom/miniforge/base/lib/python3.9/site-packages/starlette/middleware/errors.py", line 181, in __call__
    raise exc
  File "/opt/homebrew/Caskroom/miniforge/base/lib/python3.9/site-packages/starlette/middleware/errors.py", line 159, in __call__
    await self.app(scope, receive, _send)
  File "/opt/homebrew/Caskroom/miniforge/base/lib/python3.9/site-packages/starlette/middleware/cors.py", line 92, in __call__
    await self.simple_response(scope, receive, send, request_headers=headers)
  File "/opt/homebrew/Caskroom/miniforge/base/lib/python3.9/site-packages/starlette/middleware/cors.py", line 147, in simple_response
    await self.app(scope, receive, send)
  File "/opt/homebrew/Caskroom/miniforge/base/lib/python3.9/site-packages/starlette/exceptions.py", line 87, in __call__
    raise exc
  File "/opt/homebrew/Caskroom/miniforge/base/lib/python3.9/site-packages/starlette/exceptions.py", line 76, in __call__
    await self.app(scope, receive, sender)
  File "/opt/homebrew/Caskroom/miniforge/base/lib/python3.9/site-packages/fastapi/middleware/asyncexitstack.py", line 21, in __call__
    raise e
  File "/opt/homebrew/Caskroom/miniforge/base/lib/python3.9/site-packages/fastapi/middleware/asyncexitstack.py", line 18, in __call__
    await self.app(scope, receive, send)
  File "/opt/homebrew/Caskroom/miniforge/base/lib/python3.9/site-packages/starlette/routing.py", line 659, in __call__
    await route.handle(scope, receive, send)
  File "/opt/homebrew/Caskroom/miniforge/base/lib/python3.9/site-packages/starlette/routing.py", line 259, in handle
    await self.app(scope, receive, send)
  File "/opt/homebrew/Caskroom/miniforge/base/lib/python3.9/site-packages/starlette/routing.py", line 61, in app
    response = await func(request)
  File "/opt/homebrew/Caskroom/miniforge/base/lib/python3.9/site-packages/fastapi/routing.py", line 227, in app
    raw_response = await run_endpoint_function(
  File "/opt/homebrew/Caskroom/miniforge/base/lib/python3.9/site-packages/fastapi/routing.py", line 160, in run_endpoint_function
    return await dependant.call(**values)
  File "/Users/beginner/Projects/temp/fastapi-vue/backend/app/apps/permission/views.py", line 91, in setIsActive
    curd_user.setUserIsActive(db, _id=user_id, is_active=obj.is_active)
TypeError: setUserIsActive() got an unexpected keyword argument '_id'
